Workbook

Sheet ReadMe
A1: NORCO — Vestwoods Investor Model V7
A2: Exclusive Vestwoods (Haier Energy) battery storage | Egypt · Sudan · Algeria · Libya | Aug 2026 – Jul 2031
A4: Purpose | B4: Investor-grade 5-year model for NORCO's exclusive Vestwoods lithium battery storage business. The investor invests USD 1,000,000 into the EGYPT operating company for 50% of its shares.
A5: Scope | B5: Vestwoods (Haier Energy) products only — residential, C&I and telecom battery energy storage, hybrid inverters and Rescube portable power. Al Reem Plastics is not part of this plan.
A6: Markets | B6: Egypt (retail + wholesale), Sudan (committed buyer), Algeria (agency + 100% LC from Month 8), Libya (dual-hub distributors from Year 2).
A7: Container economics | B7: 40ft FCL of 340 units, landed cost USD 342,316 (factory + freight + 5% duty + 2% GOEIC + handling). Egypt revenue USD 433,281/container (50/50 retail-wholesale); export USD 393,861 (wholesale).
A8: Margins | B8: Egypt product cost 79% of Egypt revenue; export product cost 50% of export revenue (per the founder's negotiated export supply pricing). See the diligence note on the Pricing Reference sheet.
A9: Container plan Y1→Y5 | B9: Egypt 6/7/9/11/15 · Sudan 4/5/6/8/10 · Algeria 3/4/6/7/8 · Libya 0/4/5/6/8. Total 13 → 41 containers.
A10: Investment ask | B10: USD 1,000,000 core for 50% of NORCO Egypt — Tranche 1 USD 500K at close (Aug-26), Tranche 2 USD 500K at Month 4 (milestone-gated) — plus an optional USD 500K accelerator (ceiling USD 1.5M).
A11: Shareholding | B11: NORCO Egypt: Investor 50% | NORCO UAE 20% | Founder 20% | Partner A 5% | Partner B 5%. Founder-side combined interest 40% (20% direct + 20% via NORCO UAE).
A12: Supplier terms | B12: Year 1: Sinosure-backed — containers 1-4 to the shipping schedule, 5-13 at 10% down + 90% at 3-month credit. Year 2+: 10% down + 90% at 3-month credit on all POs.
A13: Currency & FX | B13: USD throughout. Planning rate USD 1 = EGP 53. Corporate tax 22.5% on net profit; Year-1 tax computed with loss carry-forward.
A14: Sheets | B14: Key Assumptions | Pre-Op Investment | Pricing Reference | Staff Plan | Monthly P&L Year 1 | Annual P&L Summary Y1-Y5 | Cash Flow Year 1 | 5Y Cash Flow | Market Detail | Funding & Returns | Shareholding | Dashboard
A15: Version | B15: V7 (Vestwoods) — 14 July 2026. Strictly Private & Confidential. Prepared by Fadi Jannan, Managing Director.

Sheet Key Assumptions
A1: Key Assumptions
A2: Vestwoods-only plan basis | Blue = key input
A4: Parameter | B4: Value / Assumption | C4: Notes
A5: ► GENERAL
A6: Business start | B6: August 2026 | C6: Month 1 = Aug-26; fiscal years run Aug–Jul
A7: Scope | B7: Vestwoods (Haier Energy) products only | C7: Residential, C&I, telecom BESS + inverters
A8: Investment vehicle | B8: NORCO Egypt (operating company) | C8: Investor subscribes for 50%; NORCO UAE holds 20%
A9: FX planning rate | B9: USD 1 = EGP 53 | C9: Conservative vs spot ~49–51
A10: Corporate tax | B10: 22.5% on net profit | C10: Loss carry-forward applied in Year 1
A11: ► CONTAINER ECONOMICS
A12: Container | B12: 340 units / 40ft FCL, landed COGS USD 342,316 | C12: Factory + USD 6,865 freight + 5% duty + 2% GOEIC + handling
A13: Egypt revenue / container | B13: USD 433,281 (50% retail / 50% wholesale) | C13: 21.0% blended margin; product cost 79% of revenue
A14: Export revenue / container | B14: USD 393,861 (wholesale) | C14: Sudan/Algeria/Libya; product cost 50% of revenue (founder's supply pricing)
A15: Lead time | B15: 45–55 days PO → Egypt warehouse | C15: Factory 15–20 + sea 18 + clearance 7–10 days
A16: Supplier terms Y1 | B16: Sinosure: containers 1-4 to schedule; 5-13 at 10% down + 90% at 3-month credit | C16: Keeps the Year-1 working-capital need to ~USD 0.9M
A17: Supplier terms Y2+ | B17: 10% down + 90% at 3-month credit on all POs | C17: ~22.5% of purchases outstanding at year end
A18: ► REVENUE
A19: Egypt containers Y1→Y5 | B19: 6 / 7 / 9 / 11 / 15 | C19: I LOCK wholesale + direct/dealer retail
A20: Sudan containers Y1→Y5 | B20: 4 / 5 / 6 / 8 / 10 | C20: Committed buyer; 50% advance + 50% delivery
A21: Algeria containers Y1→Y5 | B21: 3 / 4 / 6 / 7 / 8 | C21: Agency + 100% LC before shipment from Month 8
A22: Libya containers Y2→Y5 | B22: 0 / 4 / 5 / 6 / 8 | C22: Dual-hub distributors from Year 2
A23: Sales commissions | B23: 4% of Egypt sales | C23: Variable, paid monthly
A24: Egypt exhibitions | B24: USD 15,000 Y1 (2 events) rising to USD 35K by Y5 | C24: Electricx / Solar & Storage Cairo booths (in marketing)
A25: ► CUSTOMER TERMS
A26: Egypt customers | B26: 30–60 days (avg 45); 1-month collection lag | C26: Invoice on delivery
A27: Sudan | B27: 50% advance at order + 50% on delivery | C27: Cash before/at shipment
A28: Algeria | B28: 100% LC before shipment (FOB Jebel Ali) | C28: Licensed importer; zero in-country exposure
A29: Libya | B29: Advance / confirmed LC | C29: From Year 2, dual-hub distributors
A30: ► FACILITIES & STAFF
A31: Showroom #1 | B31: 6th October City — OPERATIONAL | C31: EGP 10,000/mo = USD 200; renovated & furnished
A32: Showroom #2 | B32: New Cairo ~100 sqm — opens Month 1 | C32: USD 2,500/month
A33: Office | B33: New Cairo, ~100 sqm furnished | C33: USD 3,000/month
A34: Warehouse | B34: 300–700 sqm — 6th Oct / Sheikh Zayed / New Cairo | C34: USD 3,000/month; located on best available cost
A35: Sales compensation | B35: Salary + 4% commission on Egypt sales | C35: Performance incentive on top of base
A36: Headcount | B36: 21 (M12) → 55 (Year 5) | C36: Full roster in Staff Plan sheet
A37: ► FUNDING
A38: Investment | B38: USD 1,000,000 for 50% of NORCO Egypt | C38: T1 500K + T2 500K; optional 500K accelerator (ceiling 1.5M)
A39: Peak funding need | B39: USD 915,603 (self-funded deficit, Jan-27) | C39: Covered by the raise; minimum cash +USD 84,397
A40: Dividend policy | B40: 100% of net profit distributed, in arrears | C40: Investor receives 50% of each distribution

Sheet Pre-Op Investment
A1: Pre-Operational Investment (Already Spent by Founder)
A2: Incurred before the August 2026 launch — demonstrates founder commitment and operational readiness
A4: Description | B4: Date | C4: Original Amount | D4: USD | E4: Category
A5: Showroom renovation — 6th October City | B5: Jun 2026 | C5: EGP 82,000 | D5: 1640 | E5: Capex — Fit-out
A6: Showroom furniture & fittings | B6: Jun 2026 | C6: EGP 85,000 | D6: 1700 | E6: Capex — Fit-out
A7: Security cameras & CCTV | B7: Jun 2026 | C7: EGP 7,500 | D7: 150 | E7: Capex — Security
A8: Additional setup & equipment | B8: Jun 2026 | C8: EGP 50,000 | D8: 1000 | E8: Capex — Equipment
A9: Legal & licensing — Egypt company registration | B9: Jul 2025 | C9: EGP 87,000 | D9: 1740 | E9: OpEx — Legal/Egypt
A10: Legal & licensing — import permits Egypt | B10: Jun 2026 | C10: EGP 80,000 | D10: 1600 | E10: OpEx — Legal/Egypt
A11: UAE business licence — NORCO General Trading LLC | B11: 2025–2026 | C11: AED 15,000 | D11: 4084 | E11: OpEx — Legal/UAE
A12: Showroom rent — pre-operations (2 months) | B12: Jun–Jul 2026 | C12: EGP 20,000 | D12: 400 | E12: OpEx — Rent
A13: Sales representative salary — 2 months pre-launch | B13: Jun–Jul 2026 | C13: 2 × USD 500 | D13: 1000 | E13: OpEx — Salaries
A14: Products purchased & sold through showroom (pre-launch trading) | B14: Jun–Jul 2026 | C14: EGP 31,948.50 | D14: 603 | E14: Working capital — Inventory
A15: Company branding, logo & stationery | B15: 2025 | C15: USD 300 | D15: 300 | E15: OpEx — Marketing
A16: Corporate website — norcotrading.com | B16: 2025 | C16: USD 300 | D16: 300 | E16: OpEx — Marketing
A17: TOTAL PRE-OPERATIONAL INVESTMENT | D17: =SUM(D5:D16)
A19: Note: EGP 31,948.50 of product stock was purchased and sold through the operating showroom before launch — live proof of demand at the retail point of sale.

Sheet Pricing Reference
A1: Pricing Reference — Vestwoods
A2: Verified unit pricing (EGP 53 = USD 1) | 40ft container USD 6,865 shipping | landed = factory + freight + 5% duty + 2% GOEIC + handling
A4: Model | B4: Description | C4: Qty / 40ft | D4: Factory | E4: Landed COGS | F4: Wholesale | G4: Retail USD | H4: Retail EGP
A5: VE51100L | B5: Smart Battery 5.12kWh | C5: 70 | D5: 672 | E5: 988 | F5: 1137 | G5: 1364 | H5: 72292
A6: VE51200L | B6: Smart Battery 10.24kWh | C6: 24 | D6: 1200 | E6: 1748 | F6: 2011 | G6: 2413 | H6: 127889
A7: VE51314L | B7: Smart Battery 16.07kWh | C7: 32 | D7: 1560 | E7: 2266 | F7: 2607 | G7: 3129 | H7: 165837
A8: VEH-T20KA3 | B8: 3-Phase Inverter 20kW | C8: 24 | D8: 1870 | E8: 2713 | F8: 3121 | G8: 3745 | H8: 198485
A9: HEH-S6KB3 | B9: Hybrid Inverter 6kW | C9: 70 | D9: 390 | E9: 582 | F9: 670 | G9: 804 | H9: 42612
A10: VEP500W | B10: Rescube Portable 0.5kW/1kWh | C10: 40 | D10: 145 | E10: 229 | F10: 264 | G10: 317 | H10: 16801
A11: VEP1K20 | B11: Rescube All-in-One 1kW/2kWh | C11: 80 | D11: 365 | E11: 546 | F11: 628 | G11: 754 | H11: 39962
A12: CONTAINER TOTALS (340 units) | B12: 40ft FCL China → Alexandria | C12: =SUM(C5:C11) | D12: 239805 | E12: 342316 | F12: 393861 | G12: 472680
A13: • Egypt container revenue (50% retail / 50% wholesale): USD 433,281 — product cost 79% of revenue (21.0% margin).
A14: • Export container revenue (wholesale, Sudan/Algeria/Libya): USD 393,861 — booked at 50% product cost per the founder's negotiated export supply pricing.
A15: • DILIGENCE NOTE: at the USD 342,316 landed container cost, USD 393,861 wholesale implies a ~13% margin. The 50% export margin in this model rests on the supply agreement — confirm before relying on the export gross margin.

Sheet Staff Plan
A1: Staffing Plan & Monthly Payroll (USD)
A2: Phased hiring | base salaries (pre-15% benefits) | Year-1 monthly detail | Years 2–5 annual rosters
A4: ROLE | B4: Monthly Salary | C4: Aug-26 | D4: Sep-26 | E4: Oct-26 | F4: Nov-26 | G4: Dec-26 | H4: Jan-27 | I4: Feb-27 | J4: Mar-27 | K4: Apr-27 | L4: May-27 | M4: Jun-27 | N4: Jul-27 | O4: Y1 Total
A5: CEO / Director | B5: 8000 | C5: 8000 | D5: 8000 | E5: 8000 | F5: 8000 | G5: 8000 | H5: 8000 | I5: 8000 | J5: 8000 | K5: 8000 | L5: 8000 | M5: 8000 | N5: 8000 | O5: 96000
A6: Financial Manager | B6: 4000 | C6: 4000 | D6: 4000 | E6: 4000 | F6: 4000 | G6: 4000 | H6: 4000 | I6: 4000 | J6: 4000 | K6: 4000 | L6: 4000 | M6: 4000 | N6: 4000 | O6: 48000
A7: Operations Manager | B7: 4000 | C7: 4000 | D7: 4000 | E7: 4000 | F7: 4000 | G7: 4000 | H7: 4000 | I7: 4000 | J7: 4000 | K7: 4000 | L7: 4000 | M7: 4000 | N7: 4000 | O7: 48000
A8: Marketing Manager | B8: 1500 | C8: – | D8: – | E8: 1500 | F8: 1500 | G8: 1500 | H8: 1500 | I8: 1500 | J8: 1500 | K8: 1500 | L8: 1500 | M8: 1500 | N8: 1500 | O8: 15000
A9: HR Manager | B9: 1000 | C9: – | D9: – | E9: 1000 | F9: 1000 | G9: 1000 | H9: 1000 | I9: 1000 | J9: 1000 | K9: 1000 | L9: 1000 | M9: 1000 | N9: 1000 | O9: 10000
A10: Sales Manager | B10: 3000 | C10: – | D10: 3000 | E10: 3000 | F10: 3000 | G10: 3000 | H10: 3000 | I10: 3000 | J10: 3000 | K10: 3000 | L10: 3000 | M10: 3000 | N10: 3000 | O10: 33000
A11: Warehouse Manager | B11: 1200 | C11: 1200 | D11: 1200 | E11: 1200 | F11: 1200 | G11: 1200 | H11: 1200 | I11: 1200 | J11: 1200 | K11: 1200 | L11: 1200 | M11: 1200 | N11: 1200 | O11: 14400
A12: Accountant #1 | B12: 800 | C12: – | D12: 800 | E12: 800 | F12: 800 | G12: 800 | H12: 800 | I12: 800 | J12: 800 | K12: 800 | L12: 800 | M12: 800 | N12: 800 | O12: 8800
A13: Accountant #2 | B13: 800 | C13: – | D13: – | E13: – | F13: – | G13: – | H13: – | I13: – | J13: 800 | K13: 800 | L13: 800 | M13: 800 | N13: 800 | O13: 4000
A14: Showroom Manager #1 (6th October) | B14: 500 | C14: 500 | D14: 500 | E14: 500 | F14: 500 | G14: 500 | H14: 500 | I14: 500 | J14: 500 | K14: 500 | L14: 500 | M14: 500 | N14: 500 | O14: 6000
A15: Showroom Manager #2 (New Cairo) | B15: 800 | C15: – | D15: 800 | E15: 800 | F15: 800 | G15: 800 | H15: 800 | I15: 800 | J15: 800 | K15: 800 | L15: 800 | M15: 800 | N15: 800 | O15: 8800
A16: Sales Staff #1 | B16: 600 | C16: – | D16: – | E16: 600 | F16: 600 | G16: 600 | H16: 600 | I16: 600 | J16: 600 | K16: 600 | L16: 600 | M16: 600 | N16: 600 | O16: 6000
A17: Sales Staff #2 | B17: 600 | C17: – | D17: – | E17: – | F17: 600 | G17: 600 | H17: 600 | I17: 600 | J17: 600 | K17: 600 | L17: 600 | M17: 600 | N17: 600 | O17: 5400
A18: Sales Staff #3 | B18: 600 | C18: – | D18: – | E18: – | F18: – | G18: – | H18: 600 | I18: 600 | J18: 600 | K18: 600 | L18: 600 | M18: 600 | N18: 600 | O18: 4200
A19: Sales Staff #4 | B19: 600 | C19: – | D19: – | E19: – | F19: – | G19: – | H19: – | I19: – | J19: 600 | K19: 600 | L19: 600 | M19: 600 | N19: 600 | O19: 3000
A20: Driver #1 | B20: 500 | C20: 500 | D20: 500 | E20: 500 | F20: 500 | G20: 500 | H20: 500 | I20: 500 | J20: 500 | K20: 500 | L20: 500 | M20: 500 | N20: 500 | O20: 6000
A21: Driver #2 | B21: 500 | C21: – | D21: – | E21: – | F21: 500 | G21: 500 | H21: 500 | I21: 500 | J21: 500 | K21: 500 | L21: 500 | M21: 500 | N21: 500 | O21: 4500
A22: Administrative Asst #1 | B22: 600 | C22: 600 | D22: 600 | E22: 600 | F22: 600 | G22: 600 | H22: 600 | I22: 600 | J22: 600 | K22: 600 | L22: 600 | M22: 600 | N22: 600 | O22: 7200
A23: Administrative Asst #2 | B23: 600 | C23: – | D23: – | E23: – | F23: – | G23: – | H23: 600 | I23: 600 | J23: 600 | K23: 600 | L23: 600 | M23: 600 | N23: 600 | O23: 4200
A24: Warehouse Staff #1 | B24: 600 | C24: – | D24: – | E24: – | F24: 600 | G24: 600 | H24: 600 | I24: 600 | J24: 600 | K24: 600 | L24: 600 | M24: 600 | N24: 600 | O24: 5400
A25: Warehouse Staff #2 | B25: 600 | C25: – | D25: – | E25: – | F25: – | G25: – | H25: – | I25: – | J25: 600 | K25: 600 | L25: 600 | M25: 600 | N25: 600 | O25: 3000
A26: TOTAL BASE SALARIES | C26: =SUM(C5:C25) | D26: =SUM(D5:D25) | E26: =SUM(E5:E25) | F26: =SUM(F5:F25) | G26: =SUM(G5:G25) | H26: =SUM(H5:H25) | I26: =SUM(I5:I25) | J26: =SUM(J5:J25) | ... O26: =SUM(O5:O25)
A27: Social Insurance & Benefits (15%) | C27: =C26*0.15 | D27: =D26*0.15 | E27: =E26*0.15 | F27: =F26*0.15 | G27: =G26*0.15 | H27: =H26*0.15 | I27: =I26*0.15 | J27: =J26*0.15 | ... O27: =O26*0.15
A28: TOTAL PERSONNEL (base + benefits) | C28: =C26*1.15 | D28: =D26*1.15 | E28: =E26*1.15 | F28: =F26*1.15 | G28: =G26*1.15 | H28: =H26*1.15 | I28: =I26*1.15 | J28: =J26*1.15 | ... O28: =O26*1.15
A30: Sales commissions (4% of Egypt sales) are variable pay on top — see Monthly P&L. Headcount reaches 21 by Month 12.
A32: YEAR 2 (Aug 2027 – Jul 2028) — 26 staff
A33: Additions | B33: + Administrative Asst #3, Logistics Coordinator, Sales Staff #5–6, Customer Service Manager, Technical Specialist, Driver #3
A34: Total base salaries (annual) | B34: 435600
A35: Social insurance & benefits (15%) | B35: 65340
A36: Personnel sub-total | B36: 500940
A37: Sales commissions (4% of Egypt sales USD 3,119,380) | B37: 124775
A38: TOTAL ANNUAL PERSONNEL COST | B38: 625715
A40: YEAR 3 (Aug 2028 – Jul 2029) — 35 staff
A41: Additions | B41: + Alexandria Branch (manager, 2 sales, admin), Finance Analyst, Supply Chain Analyst, Senior Sales Executive, Installation Engineers #1–2
A42: Total base salaries (annual) | B42: 555600
A43: Social insurance & benefits (15%) | B43: 83340
A44: Personnel sub-total | B44: 638940
...

Sheet Monthly P&L Year 1
A1: Monthly Profit & Loss Statement — Year 1 (August 2026 – July 2027)
A2: Vestwoods only | USD | Egypt product cost 79% of Egypt sales; export product cost 50% of export sales
A4: DESCRIPTION | B4: Aug-26 | C4: Sep-26 | D4: Oct-26 | E4: Nov-26 | F4: Dec-26 | G4: Jan-27 | H4: Feb-27 | I4: Mar-27 | J4: Apr-27 | K4: May-27 | L4: Jun-27 | M4: Jul-27 | N4: TOTAL Year 1
A5: REVENUE
A6: Egypt — Vestwoods (6 containers) | B6: 20000 | C6: 40000 | D6: 119483 | E6: 200000 | F6: 220000 | G6: 230000 | H6: 220000 | I6: 230000 | J6: 270000 | K6: 300000 | L6: 350000 | M6: 400000 | N6: =SUM(B6:M6)
A7: Sudan — Vestwoods (4 containers) | B7: 0 | C7: 0 | D7: 0 | E7: 0 | F7: 0 | G7: 393861 | H7: 0 | I7: 393861 | J7: 0 | K7: 393861 | L7: 0 | M7: 393861 | N7: =SUM(B7:M7)
A8: Algeria — Vestwoods, 100% LC (3 containers) | B8: 0 | C8: 0 | D8: 0 | E8: 0 | F8: 0 | G8: 0 | H8: 0 | I8: 393861 | J8: 0 | K8: 393861 | L8: 0 | M8: 393861 | N8: =SUM(B8:M8)
A9: TOTAL REVENUE | B9: 20000 | C9: 40000 | D9: 119483 | E9: 200000 | F9: 220000 | G9: 623861 | H9: 220000 | I9: 1017722 | J9: 270000 | K9: 1087722 | L9: 350000 | M9: 1187722 | N9: =SUM(B9:M9)
A10: COST OF GOODS SOLD
A11: Egypt product cost (79% of Egypt sales) | B11: 15800 | C11: 31600 | D11: 94391.6 | E11: 158000 | F11: 173800 | G11: 181700 | H11: 173800 | I11: 181700 | J11: 213300 | K11: 237000 | L11: 276500 | M11: 316000 | N11: =SUM(B11:M11)
A12: Sudan product cost (50% of Sudan sales) | B12: 0 | C12: 0 | D12: 0 | E12: 0 | F12: 0 | G12: 196930.5 | H12: 0 | I12: 196930.5 | J12: 0 | K12: 196930.5 | L12: 0 | M12: 196930.5 | N12: =SUM(B12:M12)
A13: Algeria product cost (50% of Algeria sales) | B13: 0 | C13: 0 | D13: 0 | E13: 0 | F13: 0 | G13: 0 | H13: 0 | I13: 196930.5 | J13: 0 | K13: 196930.5 | L13: 0 | M13: 196930.5 | N13: =SUM(B13:M13)
A14: TOTAL COGS | B14: 15800 | C14: 31600 | D14: 94391.6 | E14: 158000 | F14: 173800 | G14: 378630.5 | H14: 173800 | I14: 575561 | J14: 213300 | K14: 630861 | L14: 276500 | M14: 709861 | N14: =SUM(B14:M14)
A15: GROSS PROFIT | B15: 4200 | C15: 8400 | D15: 25091.4 | E15: 42000 | F15: 46200 | G15: 245230.5 | H15: 46200 | I15: 442161 | J15: 56700 | K15: 456861 | L15: 73500 | M15: 477861 | N15: =SUM(B15:M15)
A16: OPERATING EXPENSES — PERSONNEL
A17: Total base salaries (Staff Plan roster) | B17: 18800 | C17: 23400 | D17: 26500 | E17: 28200 | F17: 28200 | G17: 29400 | H17: 29400 | I17: 31400 | J17: 31400 | K17: 31400 | L17: 31400 | M17: 31400 | N17: =SUM(B17:M17)
A18: Social insurance & benefits (15%) | B18: 2820 | C18: 3510 | D18: 3975 | E18: 4230 | F18: 4230 | G18: 4410 | H18: 4410 | I18: 4710 | J18: 4710 | K18: 4710 | L18: 4710 | M18: 4710 | N18: =SUM(B18:M18)
A19: Sales commissions (4% of Egypt sales) | B19: 800 | C19: 1600 | D19: 4779.3 | E19: 8000 | F19: 8800 | G19: 9200 | H19: 8800 | I19: 9200 | J19: 10800 | K19: 12000 | L19: 14000 | M19: 16000 | N19: =SUM(B19:M19)
A20: TOTAL PERSONNEL | B20: 22420 | C20: 28510 | D20: 35254.3 | E20: 40430 | F20: 41230 | G20: 43010 | H20: 42610 | I20: 45310 | J20: 46910 | K20: 48110 | L20: 50110 | M20: 52110 | N20: =SUM(B20:M20)
A21: OPERATING EXPENSES — FACILITIES, OPS, MARKETING, G&A
A22: Showroom #1 — 6th October City (existing) | B22: 200 | C22: 200 | D22: 200 | E22: 200 | F22: 200 | G22: 200 | H22: 200 | I22: 200 | J22: 200 | K22: 200 | L22: 200 | M22: 200 | N22: =SUM(B22:M22)
A23: Showroom #2 — New Cairo ~100 sqm (opens Month 1) | B23: 2500 | C23: 2500 | D23: 2500 | E23: 2500 | F23: 2500 | G23: 2500 | H23: 2500 | I23: 2500 | J23: 2500 | K23: 2500 | L23: 2500 | M23: 2500 | N23: =SUM(B23:M23)
A24: Office — New Cairo 100 sqm furnished | B24: 6000 | C24: 3000 | D24: 3000 | E24: 3000 | F24: 3000 | G24: 3000 | H24: 3000 | I24: 3000 | J24: 3000 | K24: 3000 | L24: 3000 | M24: 3000 | N24: =SUM(B24:M24)
A25: Warehouse — 6th Oct / Sheikh Zayed / New Cairo | B25: 3000 | C25: 3000 | D25: 3000 | E25: 3000 | F25: 3000 | G25: 3000 | H25: 3000 | I25: 3000 | J25: 3000 | K25: 3000 | L25: 3000 | M25: 3000 | N25: =SUM(B25:M25)
A26: Utilities | B26: 400 | C26: 400 | D26: 700 | E26: 700 | F26: 700 | G26: 700 | H26: 700 | I26: 700 | J26: 700 | K26: 700 | L26: 700 | M26: 700 | N26: =SUM(B26:M26)
A27: Vehicles & fuel | B27: 800 | C27: 800 | D27: 800 | E27: 1500 | F27: 1500 | G27: 1500 | H27: 1500 | I27: 1500 | J27: 1500 | K27: 1500 | L27: 1500 | M27: 1500 | N27: =SUM(B27:M27)
A28: Marketing & promotions (incl. exhibitions M3) | B28: 7000 | C28: 6300 | D28: 12000 | E28: 5000 | F28: 4400 | G28: 3900 | H28: 3900 | I28: 3900 | J28: 3300 | K28: 3300 | L28: 3300 | M28: 3300 | N28: =SUM(B28:M28)
A29: General & administrative | B29: 10700 | C29: 6900 | D29: 6900 | E29: 3900 | F29: 3900 | G29: 3700 | H29: 3500 | I29: 3500 | J29: 3500 | K29: 3500 | L29: 3500 | M29: 3500 | N29: =SUM(B29:M29)
A30: Depreciation & amortisation (fit-out, 3-yr) | B30: 1400 | C30: 1400 | D30: 1400 | E30: 1400 | F30: 1400 | G30: 1400 | H30: 1400 | I30: 1400 | J30: 1400 | K30: 1400 | L30: 1400 | M30: 1400 | N30: =SUM(B30:M30)
A31: TOTAL OPERATING EXPENSES | B31: 54420 | C31: 53010 | D31: 65754.3 | E31: 61630 | F31: 61830 | G31: 62910 | H31: 62310 | I31: 65010 | J31: 66010 | K31: 67210 | L31: 69210 | M31: 71210 | N31: =SUM(B31:M31)
A32: EBIT (OPERATING PROFIT) | B32: -50220 | C32: -44610 | D32: -40662.9 | E32: -19630 | F32: -15630 | G32: 182320.5 | H32: -16110 | I32: 377151 | J32: -9310 | K32: 389651 | L32: 4290 | M32: 406651 | N32: =SUM(B32:M32)
A33: Interest on trade finance (est.) | B33: 0 | C33: 500 | D33: 500 | E33: 500 | F33: 500 | G33: 500 | H33: 500 | I33: 500 | J33: 500 | K33: 500 | L33: 500 | M33: 500 | N33: =SUM(B33:M33)
... A36: NET PROFIT / (LOSS) | B36: -50220 | C36: -45110 | D36: -41162.9 | E36: -20130 | F36: -16130 | G36: 179780.3 | H36: -16610 | I36: 295641.8 | J36: -9810 | K36: 303799.2 | L36: 2937.3 | M36: 314767 | N36: =SUM(B36:M36)
A37: Cumulative profit / (loss) | B37: -50220 | C37: -95330 | D37: -136492.9 | E37: -156622.9 | F37: -172752.9 | G37: 7027.4 | H37: -9582.6 | I37: 286059.2 | J37: 276249.2 | K37: 580048.4 | L37: 582985.7 | M37: 897752.7 | N37: 897752.7
A39: Operating & cumulative break-even both in Month 6 (Jan-27). Egypt Y1: 6 containers | Sudan: 4 | Algeria: 3 (LC).

Sheet Annual P&L Summary Y1-Y5
A1: 5-Year Annual P&L Summary (USD)
A2: Vestwoods: Egypt 6/7/9/11/15 · Sudan 4/5/6/8/10 · Algeria 3/4/6/7/8 · Libya 0/4/5/6/8
A4: DESCRIPTION | B4: Year 1 (Aug26-Jul27) | C4: Year 2 (Aug27-Jul28) | D4: Year 3 (Aug28-Jul29) | E4: Year 4 (Aug29-Jul30) | F4: Year 5 (Aug30-Jul31) | G4: 5-YEAR TOTAL
A5: REVENUE
A6: Egypt — Vestwoods | B6: 2599483 | C6: 3119380 | D6: 3743256 | E6: 4491907 | F6: 5390288 | G6: =SUM(B6:F6)
A7: Sudan — Vestwoods | B7: 1575444 | C7: 1890533 | D7: 2268639 | E7: 2722367 | F7: 3266841 | G7: =SUM(B7:F7)
A8: Algeria — Vestwoods (100% LC) | B8: 1181583 | C8: 1417900 | D8: 1701480 | E8: 2041775 | F8: 2450131 | G8: =SUM(B8:F8)
A9: Libya — Vestwoods (from Year 2) | B9: 0 | C9: 1576000 | D9: 1891200 | E9: 2269440 | F9: 2723328 | G9: =SUM(B9:F9)
A10: TOTAL REVENUE | B10: =SUM(B6:B9) | C10: =SUM(C6:C9) | D10: =SUM(D6:D9) | E10: =SUM(E6:E9) | F10: =SUM(F6:F9) | G10: =SUM(B10:F10)
A11: COST OF GOODS SOLD
A12: Egypt product cost (79%) | B12: 2053592 | C12: 2464310 | D12: 2957172 | E12: 3548607 | F12: 4258328 | G12: =SUM(B12:F12)
A13: Export product cost (50% of Sudan+Algeria+Libya) | B13: 1378514 | C13: 2442216 | D13: 2930660 | E13: 3516791 | F13: 4220150 | G13: =SUM(B13:F13)
A14: TOTAL COGS | B14: =B12+B13 | C14: =C12+C13 | D14: =D12+D13 | E14: =E12+E13 | F14: =F12+F13 | G14: =SUM(B14:F14)
A15: GROSS PROFIT | B15: =B10-B14 | C15: =C10-C14 | D15: =D10-D14 | E15: =E10-E14 | F15: =F10-F14 | G15: =SUM(B15:F15)
A16: Gross margin % | B16: =B15/B10 | C16: =C15/C10 | D16: =D15/D10 | E16: =E15/E10 | F16: =F15/F10
A17: OPERATING EXPENSES
A18: Personnel (Staff Plan + 4% Egypt commissions) | B18: 496014 | C18: 625715 | D18: 788670 | E18: 973176 | F18: 1298912 | G18: =SUM(B18:F18)
A19: Rent & facilities (2 showrooms, office, warehouse) | B19: 115200 | C19: 115200 | D19: 135000 | E19: 175000 | F19: 220000 | G19: =SUM(B19:F19)
A20: Marketing & promotions | B20: 59600 | C20: 85000 | D20: 120000 | E20: 165000 | F20: 215000 | G20: =SUM(B20:F20)
A21: Operations, G&A & trade-finance interest | B21: 78400 | C21: 105000 | D21: 130000 | E21: 165000 | F21: 205000 | G21: =SUM(B21:F21)
A22: Depreciation & amortisation | B22: 16800 | C22: 16800 | D22: 16800 | E22: 20000 | F22: 30000 | G22: =SUM(B22:F22)
A23: TOTAL OPERATING EXPENSES | B23: =SUM(B18:B22) | C23: =SUM(C18:C22) | D23: =SUM(D18:D22) | E23: =SUM(E18:E22) | F23: =SUM(F18:F22) | G23: =SUM(B23:F23)
A24: PROFITABILITY
A25: EBIT (after interest) | B25: =B15-B23 | C25: =C15-C23 | D25: =D15-D23 | E25: =E15-E23 | F25: =F15-F23 | G25: =SUM(B25:F25)
A26: Corporate income tax (22.5%) | B26: =MAX(0,B25)*0.225 | C26: =MAX(0,C25)*0.225 | D26: =MAX(0,D25)*0.225 | E26: =MAX(0,E25)*0.225 | F26: =MAX(0,F25)*0.225 | G26: =SUM(B26:F26)
A27: NET PROFIT | B27: =B25-B26 | C27: =C25-C26 | D27: =D25-D26 | E27: =E25-E26 | F27: =F25-F26 | G27: =SUM(B27:F27)
A28: Net margin % | B28: =B27/B10 | C28: =C27/C10 | D28: =D27/D10 | E28: =E27/E10 | F28: =F27/F10
A29: Cumulative net profit | B29: =B27 | C29: =B29+C27 | D29: =C29+D27 | E29: =D29+E27 | F29: =E29+F27
A31: • Total 5-year revenue USD 48,320,975 | gross profit USD 18,550,636 | net profit USD 9,438,996
A32: • Operating & cumulative break-even both Month 6 (Jan-27). Year-1 net profit nearly matches the USD 1.0M raise.
A33: • Projected investor IRR 40% (dividends only) to 69% (incl. terminal value); MOIC 3.4x–10.0x on the USD 1.0M investment.

Sheet Cash Flow Year 1
A1: Monthly Cash Flow — Year 1 (August 2026 – July 2027)
A2: Sinosure-backed supplier credit | Egypt 1-month collection lag | Sudan 50% advance + 50% delivery | Algeria 100% LC
A4: CASH FLOW ITEM | B4: Aug-26 | C4: Sep-26 | D4: Oct-26 | E4: Nov-26 | F4: Dec-26 | G4: Jan-27 | H4: Feb-27 | I4: Mar-27 | J4: Apr-27 | K4: May-27 | L4: Jun-27 | M4: Jul-27 | N4: YEAR 1 TOTAL
A5: CASH INFLOWS
A6: Egypt collections (1-month lag, 30-day avg) | B6: 20000 | C6: 40000 | D6: 40518 | E6: 55000 | F6: 80000 | G6: 130000 | H6: 180000 | I6: 270000 | J6: 330000 | K6: 380000 | L6: 420000 | M6: 440000 | N6: =SUM(B6:M6)
A7: Sudan cash received (50% advance + 50% delivery) | B7: 0 | C7: 0 | D7: 0 | E7: 0 | F7: 0 | G7: 196930.5 | H7: 196930.5 | I7: 196930.5 | J7: 196930.5 | K7: 196930.5 | L7: 196930.5 | M7: 196930.5 | N7: =SUM(B7:M7)
A8: Algeria cash received (100% LC before shipment) | B8: 0 | C8: 0 | D8: 0 | E8: 0 | F8: 0 | G8: 0 | H8: 0 | I8: 196930.5 | J8: 196930.5 | K8: 196930.5 | L8: 196930.5 | M8: 196930.5 | N8: =SUM(B8:M8)
A9: Investor capital (T1 Aug 500K | T2 Nov 500K) | B9: 500000 | C9: 0 | D9: 0 | E9: 500000 | F9: 0 | G9: 0 | H9: 0 | I9: 0 | J9: 0 | K9: 0 | L9: 0 | M9: 0 | N9: =SUM(B9:M9)
A10: TOTAL CASH INFLOWS | B10: 520000 | C10: 40000 | D10: 40518 | E10: 555000 | F10: 80000 | G10: 326930.5 | H10: 376930.5 | I10: 663861 | J10: 723861 | K10: 773861 | L10: 813861 | M10: 833861 | N10: =SUM(B10:M10)
A11: CASH OUTFLOWS
A12: Vestwoods container payments (Sinosure schedule) | B12: 50000 | C12: 171149.5 | D12: 0 | E12: 171149.5 | F12: 342299 | G12: 342299 | H12: 0 | I12: 70000 | J12: 35000 | K12: 420000 | L12: 630000 | M12: 1015000 | N12: =SUM(B12:M12)
A13: One-time setup (fit-out, deposits, licences, demo) | B13: 50000 | C13: 0 | D13: 0 | E13: 0 | F13: 0 | G13: 0 | H13: 0 | I13: 0 | J13: 0 | K13: 0 | L13: 0 | M13: 0 | N13: =SUM(B13:M13)
A14: Operating expenses (cash, incl. commissions & interest) | B14: 53020 | C14: 51610 | D14: 64354.3 | E14: 60230 | F14: 60430 | G14: 61510 | H14: 60910 | I14: 63610 | J14: 64610 | K14: 65810 | L14: 67810 | M14: 69810 | N14: =SUM(B14:M14)
A15: TOTAL CASH OUTFLOWS | B15: 153020 | C15: 222759.5 | D15: 64354.3 | E15: 231379.5 | F15: 402729 | G15: 403809 | H15: 60910 | I15: 133610 | J15: 99610 | K15: 485810 | L15: 697810 | M15: 1084810 | N15: =SUM(B15:M15)
A16: NET MONTHLY CASH FLOW | B16: 366980 | C16: -182759.5 | D16: -23836.3 | E16: 323620.5 | F16: -322729 | G16: -76878.5 | H16: 316020.5 | I16: 530251 | J16: 624251 | K16: 288051 | L16: 116051 | M16: -250949 | N16: =SUM(B16:M16)
A17: CUMULATIVE CASH POSITION | B17: 366980 | C17: 184220.5 | D17: 160384.2 | E17: 484004.7 | F17: 161275.7 | G17: 84397.2 | H17: 400417.7 | I17: 930668.7 | J17: 1554919.7 | K17: 1842970.7 | L17: 1959021.7 | M17: 1708072.7 | N17: 1708072.7
A19: • Peak self-funded deficit (excluding investor capital): USD 915,603 — covered by the USD 1.0M raise.
A20: • Minimum cash position with the raise: USD 84,397 (Jan-27, before profits build).
A21: • Year-1 ending cash: USD 1,708,073 — funds Year-2 growth alongside the credit terms.
A22: • Sudan advances (50% at order) arrive ~2 months before delivery and partially offset container prepayments.

Sheet 5Y Cash Flow
A1: Five-Year Cash Flow (USD)
A2: Y1 from the monthly sheet. Y2+ under credit terms: 10% at PO + 90% at 3-month credit (~22.5% of purchases outstanding at year end)
A4: ITEM | B4: Year 1 | C4: Year 2 | D4: Year 3 | E4: Year 4 | F4: Year 5
A5: Customer collections | B5: 4748684 | C5: 8351691 | D5: 9552585 | E5: 11463101 | F5: 13755723
A6: Investor capital (T1 + T2) | B6: 1000000 | C6: 0 | D6: 0 | E6: 0 | F6: 0
A7: Supplier payments — current-year purchases | B7: -3246897 | C7: -3802558 | D7: -4563070 | E7: -5475683 | F7: -6570820
A8: Supplier payments — prior-year balances (credit) | B8: 0 | C8: -185208 | D8: -1103968 | E8: -1324762 | F8: -1589714
A9: Operating expenses (cash; Y1 incl. USD 50,000 one-time setup) | B9: -793714 | C9: -930915 | D9: -1173670 | E9: -1478176 | F9: -1938912
A10: Corporate tax paid (prior year, in arrears) | B10: 0 | C10: -260638 | D10: -483654 | E10: -568412 | F10: -666431
A11: Dividends paid (100% of prior-year net profit) | B11: 0 | C11: -897753 | D11: -1665918 | E11: -1957862 | F11: -2295484
A12: Capex | B12: 0 | C12: -25000 | D12: -30000 | E12: -35000 | F12: -40000
A13: NET ANNUAL CASH FLOW | B13: 1708073 | C13: 2249618 | D13: 532306 | E13: 623207 | F13: 654361
A14: CLOSING CASH POSITION | B14: 1708073 | C14: 3957691 | D14: 4489997 | E14: 5113204 | F14: 5767565
A16: MEMO — Trade receivables (Egypt, 1 month + Y1 export) | B16: 607826 | C16: 259948 | D16: 311938 | E16: 374326 | F16: 449191
A17: MEMO — Supplier balances payable next year | B17: 185208 | C17: 1103969 | D17: 1324762 | E17: 1589714 | F17: 1907658
A19: • STRENGTH — Sinosure-backed credit (10% down + 90% at 3-month credit) carries ~22.5% of each year's purchases into the next year; closing cash rises every year despite full dividend payout.
A20: • RISK — Year 1 depends on the raise: peak self-funded deficit USD 915,603 (Jan-27); the USD 1.0M raise covers it with a USD 84,397 minimum. The optional accelerator widens the buffer.
A21: • NOTE — supplier payments are modelled on P&L COGS (export at 50%). If exports are re-based to the ~13% wholesale margin implied by the landed container cost, supplier outflows rise and net cash falls — see the Pricing Reference diligence note.

Sheet Market Detail
A1: Market Detail — Vestwoods
A2: Container allocations, revenue, margins, terms and market actions per year
A4: Market / Year | B4: Containers | C4: Revenue (USD) | D4: GM % | E4: Payment terms | F4: Key market action
A5: EGYPT
A6: Year 1 | B6: 6 | C6: 2599483 | D6: 0.21 | E6: Retail + 30–60 day dealer terms | F6: Two showrooms live; dealer network build; I LOCK wholesale anchor
A7: Year 2 | B7: 7 | C7: 3119380 | D7: 0.21 | E7: Retail + 30–60 day dealer terms | F7: Alexandria coverage via dealers; first C&I quotes
A8: Year 3 | B8: 9 | C8: 3743256 | D8: 0.21 | E8: Retail + 30–60 day dealer terms | F8: Alexandria branch opens; telecom accounts
A9: Year 4 | B9: 11 | C9: 4491907 | D9: 0.21 | E9: Retail + 30–60 day dealer terms | F9: B2G/tenders desk; C&I pipeline
A10: Year 5 | B10: 15 | C10: 5390288 | D10: 0.21 | E10: Retail + 30–60 day dealer terms | F10: 40+ dealer network; CKD assembly evaluation
A11: SUDAN
A12: Year 1 | B12: 4 | C12: 1575444 | D12: 0.5 | E12: 50% advance + 50% on delivery | F12: Committed buyer orders on arrival of first containers
A13: Year 2 | B13: 5 | C13: 1890533 | D13: 0.5 | E13: 50% advance + 50% on delivery | F13: 3 dealers; add Omdurman, El Obeid
A14: Year 3 | B14: 6 | C14: 2268639 | D14: 0.5 | E14: 50% advance + 50% on delivery | F14: Telecom tower contracts
A15: Year 4 | B15: 8 | C15: 2722367 | D15: 0.5 | E15: 50% advance + 50% on delivery | F15: C&I projects; Khartoum tenders
A16: Year 5 | B16: 10 | C16: 3266841 | D16: 0.5 | E16: 50% advance + 50% on delivery | F16: Standalone Sudan office consideration
A17: ALGERIA
A18: Year 1 | B18: 3 | C18: 1181583 | D18: 0.5 | E18: 100% LC before shipment | F18: First LC orders under negotiated agency (FOB Jebel Ali)
A19: Year 2 | B19: 4 | C19: 1417900 | D19: 0.5 | E19: 100% LC before shipment | F19: Agency formalised; dealer sub-network
A20: Year 3 | B20: 6 | C20: 1701480 | D20: 0.5 | E20: 100% LC before shipment | F20: Solar programme alignment
A21: Year 4 | B21: 7 | C21: 2041775 | D21: 0.5 | E21: 100% LC before shipment | F21: C&I entries; coverage expansion
A22: Year 5 | B22: 8 | C22: 2450131 | D22: 0.5 | E22: 100% LC before shipment | F22: Scale; assess in-country JV
A23: LIBYA
A24: Year 1 | B24: — | C24: 0 | D24: — | E24: Advance / confirmed LC | F24: —
A25: Year 2 | B25: 4 | C25: 1576000 | D25: 0.5 | E25: Advance / confirmed LC | F25: Sign Tripoli + Benghazi distributors
A26: Year 3 | B26: 5 | C26: 1891200 | D26: 0.5 | E26: Advance / confirmed LC | F26: Residential solar in outage districts
A27: Year 4 | B27: 6 | C27: 2269440 | D27: 0.5 | E27: Advance / confirmed LC | F27: C&I backup; NGO/health supply
A28: Year 5 | B28: 8 | C28: 2723328 | D28: 0.5 | E28: Advance / confirmed LC | F28: Secondary-city coverage
A29: Sudan cash terms mean revenue is collected before/at shipment; Algeria LC-before-shipment carries zero receivable risk. Export GM shown at the 50% supply-pricing basis (see Pricing Reference diligence note).

Sheet Funding & Returns
A1: Funding Structure & Investor Returns
A2: USD 1,000,000 core for 50% of NORCO Egypt (T1 500K + T2 500K) | optional 500K accelerator | dividends 100% payout in arrears | terminal at 5× Year-5 net profit
A4: A. TRANCHE STRUCTURE
A5: Tranche | B5: Amount (USD) | C5: Timing | D5: Gate / purpose
A6: Tranche 1 — Launch | B6: 500000 | C6: Month 1 (Aug-26, at close) | D6: First Vestwoods containers (Sinosure credit approved), setup, opex runway
A7: Tranche 2 — Scale | B7: 500000 | C7: Month 4 (Nov-26), milestone-gated | D7: Released on ≥3 containers sold through + Sudan advances received; funds container waves 4–13
A8: Optional accelerator | B8: 500000 | C8: Months 6–12, by mutual agreement | D8: Standing buffer / faster Libya & Algeria ramp; brings total to the USD 1.5M ceiling
A9: Core total (T1+T2) | B9: =SUM(B6:B7)
A11: B. INVESTOR CASH FLOW — 50% equity of NORCO Egypt for USD 1.0M
A12: Flow (USD) | B12: Y0 (close) | C12: Year 1 | D12: Year 2 | E12: Year 3 | F12: Year 4 | G12: Year 5
A13: Capital invested | B13: -1000000 | C13: 0 | D13: 0 | E13: 0 | F13: 0 | G13: 0
A14: Dividends (50% of prior-year net profit) | B14: 0 | C14: 0 | D14: =0.5*'Annual P&L Summary Y1-Y5'!B27 | E14: =0.5*'Annual P&L Summary Y1-Y5'!C27 | F14: =0.5*'Annual P&L Summary Y1-Y5'!D27 | G14: =0.5*'Annual P&L Summary Y1-Y5'!E27
A15: Terminal value (50% × 5 × Y5 net profit) | B15: 0 | C15: 0 | D15: 0 | E15: 0 | F15: 0 | G15: =0.5*5*'Annual P&L Summary Y1-Y5'!F27
A16: Net investor cash flow | B16: =SUM(B13:B15) | C16: =SUM(C13:C15) | D16: =SUM(D13:D15) | E16: =SUM(E13:E15) | F16: =SUM(F13:F15) | G16: =SUM(G13:G15)
A17: IRR — incl. terminal value | B17: =IRR(B16:G16) | D17: MOIC | E17: =SUM(C16:G16)/-B16
A18: IRR — dividends only (excl. terminal) | B18: 0.4 | D18: MOIC | E18: 3.41
A20: C. INVESTOR PROTECTIONS
A21: • Tranche 2 released only against verified Month-4 milestones (≥3 containers sold through + Sudan advances received).
A22: • Quarterly management accounts; monthly cash & inventory reporting; USD-denominated books.
A23: • Egypt customers on max 60-day terms; Sudan cash-before-shipment; Algeria LC only; Libya advance/LC.
A24: • Exclusive Vestwoods agency (first right of engagement + non-circumvention) held within the group; assignable as security.
A25: • Founder pre-investment of USD 14,517 already deployed; board seat and reserved matters for the investor.

Sheet Shareholding
A1: Shareholding — NORCO Egypt (the investment vehicle)
A2: Investor subscribes into the Egypt operating company; NORCO UAE anchors the Vestwoods agency as a 20% shareholder
A4: Shareholder | B4: NORCO Egypt % | C4: Notes
A5: Investor (USD 1.0M capital) | B5: 0.5 | C5: Cash for 50% of NORCO Egypt; board seat; reserved matters
A6: NORCO General Trading L.L.C. (UAE) | B6: 0.2 | C6: Holds the Vestwoods exclusive agency
A7: Mohammed Fadi Jannan — Chairman & Founder | B7: 0.2 | C7: Executive lead; combined founder-side interest 40% (20% direct + 20% via NORCO UAE)
A8: Partner A | B8: 0.05 | C8: Existing partner
A9: Partner B | B9: 0.05 | C9: Existing partner
A10: TOTAL | B10: =SUM(B5:B9)
A12: • Founder-side combined interest = 40%: 20% held directly by the Chairman + 20% held via NORCO General Trading L.L.C. (UAE), which he controls.
A13: • NORCO UAE contributes the exclusive Vestwoods agency to the Egypt company under a long-term agreement.
A14: • Dividend policy: 100% of net profit distributed annually in arrears — investor receives 50% of every distribution.

Sheet Dashboard
A1: Investor Dashboard
A2: Headline metrics — NORCO Egypt, Vestwoods only
A4: Total 5-year revenue (USD) | B4: =SUM('Annual P&L Summary Y1-Y5'!B10:F10)
A5: Total 5-year net profit (USD) | B5: =SUM('Annual P&L Summary Y1-Y5'!B27:F27)
A6: Year 1 revenue (USD) | B6: ='Annual P&L Summary Y1-Y5'!B10
A7: Year 1 net profit (USD) | B7: ='Annual P&L Summary Y1-Y5'!B27
A8: Year 5 net profit (USD) | B8: ='Annual P&L Summary Y1-Y5'!F27
A9: Operating break-even | B9: Month 6 (Jan-27)
A10: Cumulative break-even | B10: Month 6 (Jan-27)
A11: Peak self-funded cash deficit (USD) | B11: 915603
A12: Year-1 ending cash with raise (USD) | B12: 1708073
A13: Year-5 closing cash (USD) | B13: 5767565
A14: Investment (USD, for 50% of NORCO Egypt) | B14: 1000000
A15: Investor IRR (dividends + terminal) | B15: 0.694
A16: Investor MOIC (dividends + terminal) | B16: 9.96
A17: Investor IRR / MOIC (dividends only) | B17: 0.4
A18: Founder pre-operational investment (USD) | B18: 14517
A20: Chart data (USD)
A21: Year | B21: Y1 | C21: Y2 | D21: Y3 | E21: Y4 | F21: Y5
A22: Revenue | B22: 5356510 | C22: 8003813 | D22: 9604575 | E22: 11525489 | F22: 13830588
A23: Gross profit | B23: 1924405 | C23: 3097286 | D23: 3716743 | E23: 4460092 | F23: 5352110
A24: Net profit | B24: 897753 | C24: 1665918 | D24: 1957862 | E24: 2295484 | F24: 2621979
